/**
 * Challenge 4 Solution: Robust Error Handler
 * Run: npx tsx 02-chat-models/samples/robust-chat.ts
 */

import { createChatModel } from "@/scripts/create-model.js";
import "dotenv/config";

interface ChatOptions {
  maxRetries?: number;
  timeout?: number;
  fallbackResponse?: string;
}

async function robustChat(
  prompt: string,
  options: ChatOptions = {}
): Promise<string> {
  const { maxRetries = 3, timeout = 30000, fallbackResponse = "I apologize, but I'm having trouble connecting right now. Please try again later." } = options;

  const model = createChatModel();

  for (let attempt = 1; attempt <= maxRetries; attempt++) {
    try {
      console.log(`üîÑ Attempt ${attempt}/${maxRetries}...`);

      const response = await model.invoke(prompt);
      console.log(`‚úÖ Success on attempt ${attempt}!\n`);

      return response.content.toString();
    } catch (error: any) {
      console.error(`‚ùå Attempt ${attempt} failed: ${error.message}`);

      // Categorize the error
      let errorType = "Unknown error";
      if (error.message.includes("401") || error.message.includes("Unauthorized")) {
        errorType = "Authentication failed (check API key)";
      } else if (error.message.includes("429") || error.message.includes("rate limit")) {
        errorType = "Rate limit exceeded";
      } else if (error.message.includes("timeout")) {
        errorType = "Request timeout";
      } else if (error.message.includes("network")) {
        errorType = "Network error";
      }

      console.log(`üìã Error type: ${errorType}`);

      // Last attempt - return fallback
      if (attempt === maxRetries) {
        console.error(`\n‚ùå All ${maxRetries} attempts failed`);
        console.log(`üí° Returning fallback response\n`);
        return fallbackResponse;
      }

      // Exponential backoff
      const waitTime = Math.pow(2, attempt) * 1000;
      console.log(`‚è≥ Waiting ${waitTime}ms before retry...\n`);
      await new Promise((resolve) => setTimeout(resolve, waitTime));
    }
  }

  return fallbackResponse;
}

async function testRobustChat() {
  console.log("üõ°Ô∏è  Robust Error Handler Test\n");
  console.log("=".repeat(80));
  console.log("\n1Ô∏è‚É£  Test: Normal Call (should succeed)\n");
  const response1 = await robustChat("What is 2+2?");
  console.log("Response:", response1);
  console.log("\n" + "=".repeat(80));
  console.log("\n2Ô∏è‚É£  Test: Invalid API Key (will retry then fallback)\n");

  // Temporarily test with invalid key
  process.env.AI_API_KEY_BACKUP = process.env.AI_API_KEY;
  process.env.AI_API_KEY = "invalid_key";

  const response2 = await robustChat("Hello", {
    maxRetries: 2,
    fallbackResponse: "Sorry, I'm having connection issues. Please try again.",
  });

  console.log("Final response:", response2);

  // Restore valid key
  process.env.AI_API_KEY = process.env.AI_API_KEY_BACKUP;

  console.log("\n" + "=".repeat(80));
  console.log("\n‚úÖ Error handling demonstration complete!");
  console.log("\nüí° Key Features Demonstrated:");
  console.log("   - Automatic retry with exponential backoff");
  console.log("   - Error categorization");
  console.log("   - Graceful fallback responses");
  console.log("   - User-friendly error messages");
}

testRobustChat().catch(console.error);
